Workbook

Sheet Assumptions
A1: KLAIM UK — MODEL ASSUMPTIONS | Change yellow cells to update entire model
A2: Yellow = input | Green = calculated from other assumptions | All P&L tabs reference this sheet
A3: ASSUMPTION | B3: VALUE | C3: NOTES / FORMULA | D3: SOURCE
A4: CAPITAL & FUNDING
A5: Bootstrap raise (GBP) | B5: 30000 | C5: Friends & Family round
A6: Pre-launch social spend (Dec 2026) | B6: 3000 | C6: From bootstrap budget
A7: Pre-seed raise (Jan 2028) | B7: 750000 | C7: Target raise
A8: Seed raise (Jan 2029) | B8: 2500000 | C8: Target raise
A9: Series A raise (Jan 2030) | B9: 8000000 | C9: Target raise
A10: Pre-seed pre-money valuation | B10: 3750000 | C10: £3M–£4M range midpoint | D10: SeedLegals 2025
A11: Seed pre-money valuation | B11: 10000000 | C11: £8M–£12M range midpoint
A12: Series A pre-money valuation | B12: 37500000 | C12: £30M–£45M range midpoint
A14: REVENUE MODEL
A15: Platform fee — standard (£/tx) | B15: 1.5 | C15: Embedded in restaurant campaign budget
A16: Platform fee — premium (£/tx) | B16: 2 | C16: Opt-in: featured drops + targeting
A17: API cost per transaction (£) | B17: 0.46 | C17: TrueLayer + GoCardless + Nordigen | D17: Finexer 2026
A18: Net revenue per standard tx (£) | B18: =B15-B17 -> 1.04 | C18: Platform fee std minus API cost
A19: Net revenue per premium tx (£) | B19: =B16-B17 -> 1.54 | C19: Platform fee prem minus API cost
A20: Analytics subscription — blended (£/brand/month) | B20: 350 | C20: £299 Insights / £599 Pro blended
A21: Avg locations per brand | B21: 10 | C21: Multi-site restaurant groups
A22: Cashback offered by restaurant (£) | B22: 10 | C22: Restaurant sets this amount
A23: Net cashback to user (£) | B23: =B22-B15 -> 8.5 | C23: Cashback offered minus platform fee
A25: USER ACQUISITION
A26: PLG referral bonus per pair (£) | B26: 10 | C26: £5 referrer + £5 referred user (Klaim funded)
A27: PLG referral share of new users — Y1 (%) | B27: 0.25 | C27: 25% of new users via referral in Y1
A28: PLG referral share of new users — Y2+ (%) | B28: 0.3 | C28: 30% of new users via referral in Y2+
A29: Blended CAC — Y1 (£/active user) | B29: 8.5 | C29: Low: restaurant organic + guerrilla dominant | D29: CAC Research 2026
A30: Blended CAC — Y2 (£/active user) | B30: 18 | C30: Growing paid share | D30: CAC Research 2026
A31: Blended CAC — Y3 (£/active user) | B31: 24 | C31: Paid dominant, brand building | D31: CAC Research 2026
A32: Blended CAC — Y4 (£/active user) | B32: 27 | C32: Scale, European expansion | D32: CAC Research 2026
A33: UK CPI blended London (£/install) | B33: 5 | C33: Meta + TikTok + ASA blended | D33: Admiral Media 2026
A34: Install to active user conversion rate (%) | B34: 0.13 | C34: Finance app benchmark | D34: Admiral Media 2026
A35: Paid CPA (£/active user) | B35: =B33/B34 -> 38.461538 | C35: CPI divided by install-to-active rate
A37: HEADCOUNT & COMPENSATION
A38: Co-Founder salary from Jan 2028 (£/year each) | B38: 75000 | C38: SeedLegals benchmark for £700K+ rounds | D38: SeedLegals 2025
A39: Founding Engineer salary from Jan 2028 (£/year each) | B39: 55000 | C39: Cengo + Yunus
A40: GTM Lead salary Y2 (£/year each) | B40: 40000 | C40: 3 x GTM Leads in 2028
A41: Experience Marketing Expert salary Y2 (£/year) | B41: 60000 | C41: Hired Month 2 of 2028
A42: Employer NI rate (%) | B42: 0.138 | C42: UK standard rate 2026 | D42: HMRC
A44: OPERATIONS
...

Sheet Y1 2027 Bootstrap
A1: KLAIM UK — Y1 BOOTSTRAP | Dec 2026: Pre-Launch (Restaurant + Diner Acquisition) | Jan–Dec 2027: Live | £30K F&F | £0 Salaries
A2: LINE ITEM | B2: Dec 26 (PRE-LAUNCH No Revenue) | C2: Jan 27 | D2: Feb 27 | E2: Mar 27 | F2: Apr 27 | G2: May 27 | H2: Jun 27 | I2: Jul 27 | J2: Aug 27 | K2: Sep 27 | L2: Oct 27 | M2: Nov 27 | N2: Dec 27 | O2: FULL YEAR
A3: OPERATING ASSUMPTIONS (yellow = input)
A4: Restaurant Venues (end of month) | B4: 150 | C4: 300 | D4: 310 | E4: 320 | F4: 330 | G4: 340 | H4: 350 | I4: 360 | J4: 370 | K4: 380 | L4: 390 | M4: 400 | N4: 420 | O4: =N4 -> 420
A5: New Restaurant Venues Acquired per Month | B5: =B4 -> 150 | C5: =C4-B4 -> 150 | D5: =D4-C4 -> 10 | E5: =E4-D4 -> 10 | F5: =F4-E4 -> 10 | G5: =G4-F4 -> 10 | H5: =H4-G4 -> 10 | I5: =I4-H4 -> 10 | J5: =J4-I4 -> 10 | ... N5: =N4-M4 -> 20 | O5: =SUM(B5:N5) -> 420
A6: Restaurant Brands | B6: =B4/Assumptions!B21 -> 15 | C6: =C4/Assumptions!B21 -> 30 | D6: =D4/Assumptions!B21 -> 31 | E6: =E4/Assumptions!B21 -> 32 | F6: =F4/Assumptions!B21 -> 33 | G6: =G4/Assumptions!B21 -> 34 | H6: =H4/Assumptions!B21 -> 35 | I6: =I4/Assumptions!B21 -> 36 | J6: =J4/Assumptions!B21 -> 37 | K6: =K4/Assumptions!B21 -> 38 | L6: =L4/Assumptions!B21 -> 39 | M6: =M4/Assumptions!B21 -> 40 | N6: =N4/Assumptions!B21 -> 42 | O6: =N6 -> 42
A7: Transactions per Venue per Month (input) | B7: 0 | C7: 3 | D7: 5 | E7: 7 | F7: 9 | G7: 11 | H7: 13 | I7: 15 | J7: 17 | K7: 18 | L7: 19 | M7: 20 | N7: 21 | O7: =SUM(B7:N7) -> 158
A8: Monthly Transactions (=Venues × Tx/Venue) | B8: =B4*B7 -> 0 | C8: =C4*C7 -> 900 | D8: =D4*D7 -> 1550 | E8: =E4*E7 -> 2240 | F8: =F4*F7 -> 2970 | G8: =G4*G7 -> 3740 | H8: =H4*H7 -> 4550 | I8: =I4*I7 -> 5400 | ... N8: =N4*N7 -> 8820 | O8: =SUM(B8:N8) -> 58710
A9: New Users Acquired | B9: 200 | C9: 200 | D9: 250 | E9: 300 | F9: 300 | G9: 350 | H9: 350 | I9: 400 | J9: 400 | K9: 450 | L9: 450 | M9: 500 | N9: 500 | O9: =SUM(B9:N9) -> 4650
A10: Active Users | B10: =B9 -> 200 | C10: =B10+C9 -> 400 | D10: =C10+D9 -> 650 | E10: =D10+E9 -> 950 | F10: =E10+F9 -> 1250 | G10: =F10+G9 -> 1600 | H10: =G10+H9 -> 1950 | I10: =H10+I9 -> 2350 | J10: =I10+J9 -> 2750 | ... N10: =M10+N9 -> 4650 | O10: =N10 -> 4650
A11: Analytics Adoption % (input) | B11: 0 | C11: 0 | D11: 0 | E11: 0 | F11: 0 | G11: 0.05 | H11: 0.08 | I11: 0.1 | J11: 0.12 | K11: 0.15 | L11: 0.18 | M11: 0.2 | N11: 0.22 | O11: =N11 -> 0.22
A12: Premium Partner Adoption % (input) | B12: 0 | C12: 0 | D12: 0 | E12: 0 | F12: 0 | G12: 0 | H12: 0 | I12: 0 | J12: 0 | K12: 0 | L12: 0 | M12: 0 | N12: 0 | O12: =N12 -> 0
A14: REVENUE
A15: Stream 1: Standard Embedded Tx Fee | B15: =B8*(1-B12)*Assumptions!B15 -> 0 | C15: 0 | D15: 0 | E15: 0 | F15: =F8*(1-F12)*Assumptions!B15 -> 4455 | G15: =G8*(1-G12)*Assumptions!B15 -> 5610 | H15: =H8*(1-H12)*Assumptions!B15 -> 6825 | I15: =I8*(1-I12)*Assumptions!B15 -> 8100 | J15: =J8*(1-J12)*Assumptions!B15 -> 9435 | K15: =K8*(1-K12)*Assumptions!B15 -> 10260 | L15: =L8*(1-L12)*Assumptions!B15 -> 11115 | M15: =M8*(1-M12)*Assumptions!B15 -> 12000 | N15: =N8*(1-N12)*Assumptions!B15 -> 13230 | O15: =SUM(B15:N15) -> 81030
A16: Stream 2: Analytics Subscription | B16: =B6*B11*Assumptions!B20 -> 0 | C16: =C6*C11*Assumptions!B20 -> 0 | D16: =D6*D11*Assumptions!B20 -> 0 | E16: =E6*E11*Assumptions!B20 -> 0 | F16: =F6*F11*Assumptions!B20 -> 0 | G16: =G6*G11*Assumptions!B20 -> 595 | H16: =H6*H11*Assumptions!B20 -> 980 | I16: =I6*I11*Assumptions!B20 -> 1260 | J16: =J6*J11*Assumptions!B20 -> 1554 | K16: =K6*K11*Assumptions!B20 -> 1995 | L16: =L6*L11*Assumptions!B20 -> 2457 | M16: =M6*M11*Assumptions!B20 -> 2800 | N16: =N6*N11*Assumptions!B20 -> 3234 | O16: =SUM(B16:N16) -> 14875
A17: TOTAL REVENUE | B17: =B15+B16 -> 0 | C17: =C15+C16 -> 0 | D17: =D15+D16 -> 0 | E17: =E15+E16 -> 0 | F17: =F15+F16 -> 4455 | G17: =G15+G16 -> 6205 | H17: =H15+H16 -> 7805 | I17: =I15+I16 -> 9360 | ... N17: =N15+N16 -> 16464 | O17: =SUM(B17:N17) -> 95905
A18: COST OF REVENUE (=Monthly Tx × Assumptions!B17 = £0.46/tx)
A19: API Costs (TrueLayer + GoCardless + Nordigen) | B19: =B8*Assumptions!B17 -> 0 | C19: =C8*Assumptions!B17 -> 414 | D19: =D8*Assumptions!B17 -> 713 | E19: =E8*Assumptions!B17 -> 1030.4 | F19: =F8*Assumptions!B17 -> 1366.2 | G19: =G8*Assumptions!B17 -> 1720.4 | H19: =H8*Assumptions!B17 -> 2093 | I19: =I8*Assumptions!B17 -> 2484 | J19: =J8*Assumptions!B17 -> 2893.4 | K19: =K8*Assumptions!B17 -> 3146.4 | L19: =L8*Assumptions!B17 -> 3408.6 | M19: =M8*Assumptions!B17 -> 3680 | N19: =N8*Assumptions!B17 -> 4057.2 | O19: =SUM(B19:N19) -> 27006.6
A20: GROSS PROFIT (=Total Revenue - API Costs) | B20: =B17-B19 -> 0 | C20: =C17-C19 -> -414 | D20: =D17-D19 -> -713 | E20: =E17-E19 -> -1030.4 | F20: =F17-F19 -> 3088.8 | G20: =G17-G19 -> 4484.6 | H20: =H17-H19 -> 5712 | I20: =I17-I19 -> 6876 | ... N20: =N17-N19 -> 12406.8 | O20: =SUM(B20:N20) -> 68898.4
A21: Gross Margin % (=Gross Profit ÷ Total Revenue) | B21: =IFERROR(B20/B17,0) -> 0 | C21: =IFERROR(C20/C17,0) -> 0 | D21: =IFERROR(D20/D17,0) -> 0 | E21: =IFERROR(E20/E17,0) -> 0 | F21: =IFERROR(F20/F17,0) -> 0.69333333 | G21: =IFERROR(G20/G17,0) -> 0.72273973 | H21: =IFERROR(H20/H17,0) -> 0.73183856 | I21: =IFERROR(I20/I17,0) -> 0.73461538 | ... O21: =IFERROR(O20/O17,0) -> 0.71840259
A23: OPERATING EXPENSES — ALL FOUNDERS ON EQUITY (£0 SALARY)
A24: HEADCOUNT (all £0 salary in Y1)
A25: Sean (Co-Founder) — £0 salary, equity only | B25: =0 -> 0 | C25: =0 -> 0 | D25: =0 -> 0 | E25: =0 -> 0 | F25: =0 -> 0 | G25: =0 -> 0 | H25: =0 -> 0 | I25: =0 -> 0 | ... O25: =0 -> 0
A26: Marc (Co-Founder) — £0 salary, equity only | B26: =0 -> 0 | C26: =0 -> 0 | D26: =0 -> 0 | E26: =0 -> 0 | F26: =0 -> 0 | G26: =0 -> 0 | H26: =0 -> 0 | I26: =0 -> 0 | ... O26: =0 -> 0
A27: Cengo (Co-Founder, Engineering) — £0 salary, equity only | B27: =0 -> 0 | C27: =0 -> 0 | D27: =0 -> 0 | E27: =0 -> 0 | F27: =0 -> 0 | G27: =0 -> 0 | H27: =0 -> 0 | I27: =0 -> 0 | ... O27: =0 -> 0
A28: Yunus (Co-Founder, Engineering) — £0 salary, equity only | B28: =0 -> 0 | C28: =0 -> 0 | D28: =0 -> 0 | E28: =0 -> 0 | F28: =0 -> 0 | G28: =0 -> 0 | H28: =0 -> 0 | I28: =0 -> 0 | ... O28: =0 -> 0
A29: GTM Lead 1 — £0 salary, equity only | B29: =0 -> 0 | C29: =0 -> 0 | D29: =0 -> 0 | E29: =0 -> 0 | F29: =0 -> 0 | G29: =0 -> 0 | H29: =0 -> 0 | I29: =0 -> 0 | ... O29: =0 -> 0
A30: GTM Lead 2 — £0 salary, equity only | B30: =0 -> 0 | C30: =0 -> 0 | D30: =0 -> 0 | E30: =0 -> 0 | F30: =0 -> 0 | G30: =0 -> 0 | H30: =0 -> 0 | I30: =0 -> 0 | ... O30: =0 -> 0
A31: TOTAL HEADCOUNT | B31: =SUM(B25:B30) -> 0 | C31: =SUM(C25:C30) -> 0 | D31: =SUM(D25:D30) -> 0 | E31: =SUM(E25:E30) -> 0 | F31: =SUM(F25:F30) -> 0 | G31: =SUM(G25:G30) -> 0 | H31: =SUM(H25:H30) -> 0 | I31: =SUM(I25:I30) -> 0 | ... N31: =SUM(N25:N30) -> 0 | O31: =SUM(B31:N31) -> 0
A32: MARKETING & DINER ACQUISITION
A33: Pre-Launch Social Ads (Dec 2026 only) | B33: 3000 | C33: 0 | D33: 0 | E33: 0 | F33: 0 | G33: 0 | H33: 0 | I33: 0 | J33: 0 | K33: 0 | L33: 0 | M33: 0 | N33: 0 | O33: =SUM(B33:N33) -> 3000
A34: PLG Referral Bonus | B34: 0 | C34: =C9*Assumptions!B27*Assumptions!B26 -> 500 | D34: =D9*Assumptions!B27*Assumptions!B26 -> 625 | E34: =E9*Assumptions!B27*Assumptions!B26 -> 750 | F34: =F9*Assumptions!B27*Assumptions!B26 -> 750 | G34: =G9*Assumptions!B27*Assumptions!B26 -> 875 | H34: =H9*Assumptions!B27*Assumptions!B26 -> 875 | I34: =I9*Assumptions!B27*Assumptions!B26 -> 1000 | J34: =J9*Assumptions!B27*Assumptions!B26 -> 1000 | K34: =K9*Assumptions!B27*Assumptions!B26 -> 1125 | L34: =L9*Assumptions!B27*Assumptions!B26 -> 1125 | M34: =M9*Assumptions!B27*Assumptions!B26 -> 1250 | N34: =N9*Assumptions!B27*Assumptions!B26 -> 1250 | O34: =SUM(B34:N34) -> 11125
A35: Performance Marketing (Paid Social) | B35: 0 | C35: 1500 | D35: 1500 | E35: 1500 | F35: 1500 | G35: 1500 | H35: 1500 | I35: 2000 | J35: 2000 | K35: 2000 | L35: 2000 | M35: 2000 | N35: 2000 | O35: =SUM(B35:N35) -> 21000
A36: Content Creation & Guerrilla Marketing | B36: 500 | C36: 500 | D36: 500 | E36: 500 | F36: 500 | G36: 500 | H36: 500 | I36: 500 | J36: 500 | K36: 500 | L36: 500 | M36: 500 | N36: 500 | O36: =SUM(B36:N36) -> 6500
A37: Window Stickers & QR Assets | B37: 0 | C37: 300 | D37: 0 | E37: 0 | F37: 0 | G37: 0 | H37: 0 | I37: 0 | J37: 0 | K37: 0 | L37: 0 | M37: 0 | N37: 0 | O37: =SUM(B37:N37) -> 300
A38: TOTAL MARKETING | B38: =SUM(B33:B37) -> 3500 | C38: =SUM(C33:C37) -> 2800 | D38: =SUM(D33:D37) -> 2625 | E38: =SUM(E33:E37) -> 2750 | F38: =SUM(F33:F37) -> 2750 | G38: =SUM(G33:G37) -> 2875 | H38: =SUM(H33:H37) -> 2875 | I38: =SUM(I33:I37) -> 3500 | ... N38: =SUM(N33:N37) -> 3750 | O38: =SUM(B38:N38) -> 41925
A39: AI Outreach Tools (£300/month from Jan) | B39: 300 | C39: 300 | D39: 300 | E39: 300 | F39: 300 | G39: 300 | H39: 300 | I39: 300 | J39: 300 | K39: 300 | L39: 300 | M39: 300 | N39: 300 | O39: =SUM(B39:N39) -> 3900
A40: Tech Infrastructure (hosting, tools) | B40: 200 | C40: 500 | D40: 500 | E40: 500 | F40: 500 | G40: 500 | H40: 500 | I40: 500 | J40: 500 | K40: 500 | L40: 500 | M40: 500 | N40: 500 | O40: =SUM(B40:N40) -> 6200
A41: Legal (FCA AR registration, T&Cs) | B41: 2500 | C41: 500 | D41: 500 | E41: 0 | F41: 0 | G41: 0 | H41: 0 | I41: 0 | J41: 0 | K41: 0 | L41: 0 | M41: 0 | N41: 0 | O41: =SUM(B41:N41) -> 3500
A42: Miscellaneous | B42: 300 | C42: 300 | D42: 300 | E42: 300 | F42: 300 | G42: 300 | H42: 300 | I42: 300 | J42: 300 | K42: 300 | L42: 300 | M42: 300 | N42: 300 | O42: =SUM(B42:N42) -> 3900
...

Sheet Y2 2028 Pre-Seed
A1: KLAIM UK — Y2 PRE-SEED (Jan–Dec 2028) | £750K Raise | Aggressive Deployment | Target £300K Closing Cash
A2: LINE ITEM | B2: Jan 28 | C2: Feb 28 | D2: Mar 28 | E2: Apr 28 | F2: May 28 | G2: Jun 28 | H2: Jul 28 | I2: Aug 28 | J2: Sep 28 | K2: Oct 28 | L2: Nov 28 | M2: Dec 28 | N2: FULL YEAR
A3: OPERATING ASSUMPTIONS (yellow = input)
A4: Restaurant Venues (end of month) | B4: 430 | C4: 450 | D4: 470 | E4: 490 | F4: 510 | G4: 530 | H4: 550 | I4: 570 | J4: 590 | K4: 610 | L4: 630 | M4: 650 | N4: =M4 -> 650
A5: New Restaurant Venues Acquired per Month | B5: =B4-'Y1 2027 Bootstrap'!N4 -> 10 | C5: =C4-B4 -> 20 | D5: =D4-C4 -> 20 | E5: =E4-D4 -> 20 | F5: =F4-E4 -> 20 | G5: =G4-F4 -> 20 | H5: =H4-G4 -> 20 | I5: =I4-H4 -> 20 | J5: =J4-I4 -> 20 | ... M5: =M4-L4 -> 20 | N5: =SUM(B5:M5) -> 230
A6: Restaurant Brands (=Venues ÷ Assumptions!B21) | B6: =B4/Assumptions!B21 -> 43 | C6: =C4/Assumptions!B21 -> 45 | D6: =D4/Assumptions!B21 -> 47 | E6: =E4/Assumptions!B21 -> 49 | F6: =F4/Assumptions!B21 -> 51 | G6: =G4/Assumptions!B21 -> 53 | H6: =H4/Assumptions!B21 -> 55 | I6: =I4/Assumptions!B21 -> 57 | J6: =J4/Assumptions!B21 -> 59 | K6: =K4/Assumptions!B21 -> 61 | L6: =L4/Assumptions!B21 -> 63 | M6: =M4/Assumptions!B21 -> 65 | N6: =M6 -> 65
A7: Transactions per Venue per Month (input) | B7: 22 | C7: 25 | D7: 28 | E7: 32 | F7: 36 | G7: 40 | H7: 44 | I7: 48 | J7: 52 | K7: 55 | L7: 58 | M7: 60 | N7: =SUM(B7:M7) -> 500
A8: Monthly Transactions | B8: =B4*B7 -> 9460 | C8: =C4*C7 -> 11250 | D8: =D4*D7 -> 13160 | E8: =E4*E7 -> 15680 | F8: =F4*F7 -> 18360 | G8: =G4*G7 -> 21200 | H8: =H4*H7 -> 24200 | I8: =I4*I7 -> 27360 | ... M8: =M4*M7 -> 39000 | N8: =SUM(B8:M8) -> 280440
A9: New Users Acquired (this month — input) | B9: 900 | C9: 900 | D9: 1200 | E9: 1500 | F9: 1700 | G9: 1900 | H9: 1900 | I9: 2000 | J9: 2000 | K9: 2100 | L9: 2100 | M9: 2265 | N9: =SUM(B9:M9) -> 20465
A10: Active Users — CUMULATIVE (starts from Y1 end) | B10: ='Y1 2027 Bootstrap'!O10+B9 -> 5550 | C10: =B10+C9 -> 6450 | D10: =C10+D9 -> 7650 | E10: =D10+E9 -> 9150 | F10: =E10+F9 -> 10850 | G10: =F10+G9 -> 12750 | H10: =G10+H9 -> 14650 | I10: =H10+I9 -> 16650 | J10: =I10+J9 -> 18650 | ... M10: =L10+M9 -> 25115 | N10: =M10 -> 25115
A11: Analytics Adoption % (input) | B11: 0.24 | C11: 0.26 | D11: 0.28 | E11: 0.3 | F11: 0.32 | G11: 0.34 | H11: 0.36 | I11: 0.38 | J11: 0.4 | K11: 0.42 | L11: 0.44 | M11: 0.46 | N11: =M11 -> 0.46
A12: Premium Partner Adoption % (input) | B12: 0 | C12: 0 | D12: 0.05 | E12: 0.08 | F12: 0.1 | G12: 0.12 | H12: 0.15 | I12: 0.18 | J12: 0.2 | K12: 0.22 | L12: 0.24 | M12: 0.25 | N12: =M12 -> 0.25
A14: REVENUE — 3 STREAMS
A15: Stream 1: Standard Tx Fee | B15: =B8*(1-B12)*Assumptions!B15 -> 14190 | C15: =C8*(1-C12)*Assumptions!B15 -> 16875 | D15: =D8*(1-D12)*Assumptions!B15 -> 18753 | E15: =E8*(1-E12)*Assumptions!B15 -> 21638.4 | F15: =F8*(1-F12)*Assumptions!B15 -> 24786 | G15: =G8*(1-G12)*Assumptions!B15 -> 27984 | H15: =H8*(1-H12)*Assumptions!B15 -> 30855 | I15: =I8*(1-I12)*Assumptions!B15 -> 33652.8 | J15: =J8*(1-J12)*Assumptions!B15 -> 36816 | K15: =K8*(1-K12)*Assumptions!B15 -> 39253.5 | L15: =L8*(1-L12)*Assumptions!B15 -> 41655.6 | M15: =M8*(1-M12)*Assumptions!B15 -> 43875 | N15: =SUM(B15:M15) -> 350334.3
A16: Stream 3: Premium Placement Fee | B16: =B8*B12*Assumptions!B16 -> 0 | C16: =C8*C12*Assumptions!B16 -> 0 | D16: =D8*D12*Assumptions!B16 -> 1316 | E16: =E8*E12*Assumptions!B16 -> 2508.8 | F16: =F8*F12*Assumptions!B16 -> 3672 | G16: =G8*G12*Assumptions!B16 -> 5088 | H16: =H8*H12*Assumptions!B16 -> 7260 | I16: =I8*I12*Assumptions!B16 -> 9849.6 | J16: =J8*J12*Assumptions!B16 -> 12272 | K16: =K8*K12*Assumptions!B16 -> 14762 | L16: =L8*L12*Assumptions!B16 -> 17539.2 | M16: =M8*M12*Assumptions!B16 -> 19500 | N16: =SUM(B16:M16) -> 93767.6
A17: Stream 2: Analytics Subscription | B17: =B6*B11*Assumptions!B20 -> 3612 | C17: =C6*C11*Assumptions!B20 -> 4095 | D17: =D6*D11*Assumptions!B20 -> 4606 | E17: =E6*E11*Assumptions!B20 -> 5145 | F17: =F6*F11*Assumptions!B20 -> 5712 | G17: =G6*G11*Assumptions!B20 -> 6307 | H17: =H6*H11*Assumptions!B20 -> 6930 | I17: =I6*I11*Assumptions!B20 -> 7581 | J17: =J6*J11*Assumptions!B20 -> 8260 | K17: =K6*K11*Assumptions!B20 -> 8967 | L17: =L6*L11*Assumptions!B20 -> 9702 | M17: =M6*M11*Assumptions!B20 -> 10465 | N17: =SUM(B17:M17) -> 81382
A18: TOTAL REVENUE | B18: =B15+B16+B17 -> 17802 | C18: =C15+C16+C17 -> 20970 | D18: =D15+D16+D17 -> 24675 | E18: =E15+E16+E17 -> 29292.2 | F18: =F15+F16+F17 -> 34170 | G18: =G15+G16+G17 -> 39379 | H18: =H15+H16+H17 -> 45045 | I18: =I15+I16+I17 -> 51083.4 | ... M18: =M15+M16+M17 -> 73840 | N18: =SUM(B18:M18) -> 525483.9
A19: COST OF REVENUE (=Monthly Tx × Assumptions!B17 = £0.46/tx)
A20: API Costs | B20: =B8*Assumptions!B17 -> 4351.6 | C20: =C8*Assumptions!B17 -> 5175 | D20: =D8*Assumptions!B17 -> 6053.6 | E20: =E8*Assumptions!B17 -> 7212.8 | F20: =F8*Assumptions!B17 -> 8445.6 | G20: =G8*Assumptions!B17 -> 9752 | H20: =H8*Assumptions!B17 -> 11132 | I20: =I8*Assumptions!B17 -> 12585.6 | J20: =J8*Assumptions!B17 -> 14112.8 | K20: =K8*Assumptions!B17 -> 15433 | L20: =L8*Assumptions!B17 -> 16808.4 | M20: =M8*Assumptions!B17 -> 17940 | N20: =SUM(B20:M20) -> 129002.4
A21: GROSS PROFIT | B21: =B18-B20 -> 13450.4 | C21: =C18-C20 -> 15795 | D21: =D18-D20 -> 18621.4 | E21: =E18-E20 -> 22079.4 | F21: =F18-F20 -> 25724.4 | G21: =G18-G20 -> 29627 | H21: =H18-H20 -> 33913 | I21: =I18-I20 -> 38497.8 | ... M21: =M18-M20 -> 55900 | N21: =SUM(B21:M21) -> 396481.5
A22: Gross Margin % | B22: =IFERROR(B21/B18,0) -> 0.75555556 | C22: =IFERROR(C21/C18,0) -> 0.75321888 | D22: =IFERROR(D21/D18,0) -> 0.75466667 | E22: =IFERROR(E21/E18,0) -> 0.7537638 | F22: =IFERROR(F21/F18,0) -> 0.75283582 | G22: =IFERROR(G21/G18,0) -> 0.75235532 | H22: =IFERROR(H21/H18,0) -> 0.75286935 | I22: =IFERROR(I21/I18,0) -> 0.75362642 | ... N22: =IFERROR(N21/N18,0) -> 0.75450742
A24: OPERATING EXPENSES
A25: HEADCOUNT (Founders + Engineers on salary + 3 GTM + Exp Marketing)
A26: Sean (Co-Founder) | B26: =Assumptions!B38/12 -> 6250 | C26: =Assumptions!B38/12 -> 6250 | D26: =Assumptions!B38/12 -> 6250 | E26: =Assumptions!B38/12 -> 6250 | F26: =Assumptions!B38/12 -> 6250 | G26: =Assumptions!B38/12 -> 6250 | H26: =Assumptions!B38/12 -> 6250 | I26: =Assumptions!B38/12 -> 6250 | J26: =Assumptions!B38/12 -> 6250 | K26: =Assumptions!B38/12 -> 6250 | L26: =Assumptions!B38/12 -> 6250 | M26: =Assumptions!B38/12 -> 6250 | N26: =SUM(B26:M26) -> 75000
A27: Marc (Co-Founder) | B27: =Assumptions!B38/12 -> 6250 | C27: =Assumptions!B38/12 -> 6250 | D27: =Assumptions!B38/12 -> 6250 | E27: =Assumptions!B38/12 -> 6250 | F27: =Assumptions!B38/12 -> 6250 | G27: =Assumptions!B38/12 -> 6250 | H27: =Assumptions!B38/12 -> 6250 | I27: =Assumptions!B38/12 -> 6250 | J27: =Assumptions!B38/12 -> 6250 | K27: =Assumptions!B38/12 -> 6250 | L27: =Assumptions!B38/12 -> 6250 | M27: =Assumptions!B38/12 -> 6250 | N27: =SUM(B27:M27) -> 75000
A28: Cengo (Co-Founder, Engineering) | B28: =Assumptions!B39*(1+Assumptions!B42)/12 -> 5215.8333 | C28: =Assumptions!B39*(1+Assumptions!B42)/12 -> 5215.8333 | D28: =Assumptions!B39*(1+Assumptions!B42)/12 -> 5215.8333 | E28: =Assumptions!B39*(1+Assumptions!B42)/12 -> 5215.8333 | F28: =Assumptions!B39*(1+Assumptions!B42)/12 -> 5215.8333 | G28: =Assumptions!B39*(1+Assumptions!B42)/12 -> 5215.8333 | H28: =Assumptions!B39*(1+Assumptions!B42)/12 -> 5215.8333 | I28: =Assumptions!B39*(1+Assumptions!B42)/12 -> 5215.8333 | J28: =Assumptions!B39*(1+Assumptions!B42)/12 -> 5215.8333 | K28: =Assumptions!B39*(1+Assumptions!B42)/12 -> 5215.8333 | L28: =Assumptions!B39*(1+Assumptions!B42)/12 -> 5215.8333 | M28: =Assumptions!B39*(1+Assumptions!B42)/12 -> 5215.8333 | N28: =SUM(B28:M28) -> 62590
A29: Yunus (Co-Founder, Engineering) | B29: =Assumptions!B39*(1+Assumptions!B42)/12 -> 5215.8333 | C29: =Assumptions!B39*(1+Assumptions!B42)/12 -> 5215.8333 | D29: =Assumptions!B39*(1+Assumptions!B42)/12 -> 5215.8333 | E29: =Assumptions!B39*(1+Assumptions!B42)/12 -> 5215.8333 | F29: =Assumptions!B39*(1+Assumptions!B42)/12 -> 5215.8333 | G29: =Assumptions!B39*(1+Assumptions!B42)/12 -> 5215.8333 | H29: =Assumptions!B39*(1+Assumptions!B42)/12 -> 5215.8333 | I29: =Assumptions!B39*(1+Assumptions!B42)/12 -> 5215.8333 | J29: =Assumptions!B39*(1+Assumptions!B42)/12 -> 5215.8333 | K29: =Assumptions!B39*(1+Assumptions!B42)/12 -> 5215.8333 | L29: =Assumptions!B39*(1+Assumptions!B42)/12 -> 5215.8333 | M29: =Assumptions!B39*(1+Assumptions!B42)/12 -> 5215.8333 | N29: =SUM(B29:M29) -> 62590
A30: GTM Lead 1 | B30: =Assumptions!B40*(1+Assumptions!B42)/12 -> 3793.3333 | C30: =Assumptions!B40*(1+Assumptions!B42)/12 -> 3793.3333 | D30: =Assumptions!B40*(1+Assumptions!B42)/12 -> 3793.3333 | E30: =Assumptions!B40*(1+Assumptions!B42)/12 -> 3793.3333 | F30: =Assumptions!B40*(1+Assumptions!B42)/12 -> 3793.3333 | G30: =Assumptions!B40*(1+Assumptions!B42)/12 -> 3793.3333 | H30: =Assumptions!B40*(1+Assumptions!B42)/12 -> 3793.3333 | I30: =Assumptions!B40*(1+Assumptions!B42)/12 -> 3793.3333 | J30: =Assumptions!B40*(1+Assumptions!B42)/12 -> 3793.3333 | K30: =Assumptions!B40*(1+Assumptions!B42)/12 -> 3793.3333 | L30: =Assumptions!B40*(1+Assumptions!B42)/12 -> 3793.3333 | M30: =Assumptions!B40*(1+Assumptions!B42)/12 -> 3793.3333 | N30: =SUM(B30:M30) -> 45520
A31: GTM Lead 2 | B31: =Assumptions!B40*(1+Assumptions!B42)/12 -> 3793.3333 | C31: =Assumptions!B40*(1+Assumptions!B42)/12 -> 3793.3333 | D31: =Assumptions!B40*(1+Assumptions!B42)/12 -> 3793.3333 | E31: =Assumptions!B40*(1+Assumptions!B42)/12 -> 3793.3333 | F31: =Assumptions!B40*(1+Assumptions!B42)/12 -> 3793.3333 | G31: =Assumptions!B40*(1+Assumptions!B42)/12 -> 3793.3333 | H31: =Assumptions!B40*(1+Assumptions!B42)/12 -> 3793.3333 | I31: =Assumptions!B40*(1+Assumptions!B42)/12 -> 3793.3333 | J31: =Assumptions!B40*(1+Assumptions!B42)/12 -> 3793.3333 | K31: =Assumptions!B40*(1+Assumptions!B42)/12 -> 3793.3333 | L31: =Assumptions!B40*(1+Assumptions!B42)/12 -> 3793.3333 | M31: =Assumptions!B40*(1+Assumptions!B42)/12 -> 3793.3333 | N31: =SUM(B31:M31) -> 45520
A32: GTM Lead 3 | B32: =Assumptions!B40*(1+Assumptions!B42)/12 -> 3793.3333 | C32: =Assumptions!B40*(1+Assumptions!B42)/12 -> 3793.3333 | D32: =Assumptions!B40*(1+Assumptions!B42)/12 -> 3793.3333 | E32: =Assumptions!B40*(1+Assumptions!B42)/12 -> 3793.3333 | F32: =Assumptions!B40*(1+Assumptions!B42)/12 -> 3793.3333 | G32: =Assumptions!B40*(1+Assumptions!B42)/12 -> 3793.3333 | H32: =Assumptions!B40*(1+Assumptions!B42)/12 -> 3793.3333 | I32: =Assumptions!B40*(1+Assumptions!B42)/12 -> 3793.3333 | J32: =Assumptions!B40*(1+Assumptions!B42)/12 -> 3793.3333 | K32: =Assumptions!B40*(1+Assumptions!B42)/12 -> 3793.3333 | L32: =Assumptions!B40*(1+Assumptions!B42)/12 -> 3793.3333 | M32: =Assumptions!B40*(1+Assumptions!B42)/12 -> 3793.3333 | N32: =SUM(B32:M32) -> 45520
A33: Growth Marketing Manager | B33: =0 -> 0 | C33: =Assumptions!B41*(1+Assumptions!B42)/12 -> 5690 | D33: =Assumptions!B41*(1+Assumptions!B42)/12 -> 5690 | E33: =Assumptions!B41*(1+Assumptions!B42)/12 -> 5690 | F33: =Assumptions!B41*(1+Assumptions!B42)/12 -> 5690 | G33: =Assumptions!B41*(1+Assumptions!B42)/12 -> 5690 | H33: =Assumptions!B41*(1+Assumptions!B42)/12 -> 5690 | I33: =Assumptions!B41*(1+Assumptions!B42)/12 -> 5690 | J33: =Assumptions!B41*(1+Assumptions!B42)/12 -> 5690 | K33: =Assumptions!B41*(1+Assumptions!B42)/12 -> 5690 | L33: =Assumptions!B41*(1+Assumptions!B42)/12 -> 5690 | M33: =Assumptions!B41*(1+Assumptions!B42)/12 -> 5690 | N33: =SUM(B33:M33) -> 62590
A34: TOTAL HEADCOUNT | B34: =SUM(B26:B33) -> 34311.667 | C34: =SUM(C26:C33) -> 40001.667 | D34: =SUM(D26:D33) -> 40001.667 | E34: =SUM(E26:E33) -> 40001.667 | F34: =SUM(F26:F33) -> 40001.667 | G34: =SUM(G26:G33) -> 40001.667 | H34: =SUM(H26:H33) -> 40001.667 | I34: =SUM(I26:I33) -> 40001.667 | ... M34: =SUM(M26:M33) -> 40001.667 | N34: =SUM(B34:M34) -> 474330
A35: MARKETING & DINER ACQUISITION
A36: PLG Referral Bonus | B36: =B9*Assumptions!B28*Assumptions!B26 -> 2700 | C36: =C9*Assumptions!B28*Assumptions!B26 -> 2700 | D36: =D9*Assumptions!B28*Assumptions!B26 -> 3600 | E36: =E9*Assumptions!B28*Assumptions!B26 -> 4500 | F36: =F9*Assumptions!B28*Assumptions!B26 -> 5100 | G36: =G9*Assumptions!B28*Assumptions!B26 -> 5700 | H36: =H9*Assumptions!B28*Assumptions!B26 -> 5700 | I36: =I9*Assumptions!B28*Assumptions!B26 -> 6000 | J36: =J9*Assumptions!B28*Assumptions!B26 -> 6000 | K36: =K9*Assumptions!B28*Assumptions!B26 -> 6300 | L36: =L9*Assumptions!B28*Assumptions!B26 -> 6300 | M36: =M9*Assumptions!B28*Assumptions!B26 -> 6795 | N36: =SUM(B36:M36) -> 61395
A37: Performance Marketing (input) | B37: 9500 | C37: 9500 | D37: 9500 | E37: 12500 | F37: 15500 | G37: 18000 | H37: 20500 | I37: 23000 | J37: 25000 | K37: 27000 | L37: 29000 | M37: 31000 | N37: =SUM(B37:M37) -> 230000
A38: Content Creation & Influencer (input) | B38: 1500 | C38: 2000 | D38: 2000 | E38: 2000 | F38: 2500 | G38: 2500 | H38: 2500 | I38: 2500 | J38: 2500 | K38: 2500 | L38: 2500 | M38: 2500 | N38: =SUM(B38:M38) -> 27500
A39: TOTAL MARKETING | B39: =SUM(B36:B38) -> 13700 | C39: =SUM(C36:C38) -> 14200 | D39: =SUM(D36:D38) -> 15100 | E39: =SUM(E36:E38) -> 19000 | F39: =SUM(F36:F38) -> 23100 | G39: =SUM(G36:G38) -> 26200 | H39: =SUM(H36:H38) -> 28700 | I39: =SUM(I36:I38) -> 31500 | ... M39: =SUM(M36:M38) -> 40295 | N39: =SUM(B39:M39) -> 318895
A40: Restaurant Partner Acquisition (input) | B40: 3000 | C40: 2000 | D40: 2000 | E40: 2000 | F40: 1500 | G40: 1500 | H40: 1000 | I40: 1000 | J40: 1000 | K40: 500 | L40: 500 | M40: 500 | N40: =SUM(B40:M40) -> 16500
A41: AI Outreach Tools | B41: 300 | C41: 300 | D41: 300 | E41: 300 | F41: 300 | G41: 300 | H41: 300 | I41: 300 | J41: 300 | K41: 300 | L41: 300 | M41: 300 | N41: =SUM(B41:M41) -> 3600
A42: Tech Infrastructure (input) | B42: 1500 | C42: 1500 | D42: 1500 | E42: 1500 | F42: 1500 | G42: 1500 | H42: 1500 | I42: 1500 | J42: 1500 | K42: 1500 | L42: 1500 | M42: 1500 | N42: =SUM(B42:M42) -> 18000
...

Sheet Y3 2029 Seed
A1: KLAIM UK — Y3 SEED (Jan–Dec 2029) | £2.5M Raise | Maximum Deployment | Target £500K Closing Cash
A2: LINE ITEM | B2: Jan 29 | C2: Feb 29 | D2: Mar 29 | E2: Apr 29 | F2: May 29 | G2: Jun 29 | H2: Jul 29 | I2: Aug 29 | J2: Sep 29 | K2: Oct 29 | L2: Nov 29 | M2: Dec 29 | N2: FULL YEAR
A3: OPERATING ASSUMPTIONS (yellow = input)
A4: Restaurant Venues (end of month) | B4: 700 | C4: 760 | D4: 820 | E4: 890 | F4: 960 | G4: 1040 | H4: 1120 | I4: 1200 | J4: 1280 | K4: 1360 | L4: 1440 | M4: 1500 | N4: =M4 -> 1500
A5: New Restaurant Venues Acquired per Month | B5: =B4-'Y2 2028 Pre-Seed'!M4 -> 50 | C5: =C4-B4 -> 60 | D5: =D4-C4 -> 60 | E5: =E4-D4 -> 70 | F5: =F4-E4 -> 70 | G5: =G4-F4 -> 80 | H5: =H4-G4 -> 80 | I5: =I4-H4 -> 80 | J5: =J4-I4 -> 80 | ... M5: =M4-L4 -> 60 | N5: =SUM(B5:M5) -> 850
A6: Restaurant Brands (÷ Assumptions!B21) | B6: =B4/Assumptions!B21 -> 70 | C6: =C4/Assumptions!B21 -> 76 | D6: =D4/Assumptions!B21 -> 82 | E6: =E4/Assumptions!B21 -> 89 | F6: =F4/Assumptions!B21 -> 96 | G6: =G4/Assumptions!B21 -> 104 | H6: =H4/Assumptions!B21 -> 112 | I6: =I4/Assumptions!B21 -> 120 | J6: =J4/Assumptions!B21 -> 128 | K6: =K4/Assumptions!B21 -> 136 | L6: =L4/Assumptions!B21 -> 144 | M6: =M4/Assumptions!B21 -> 150 | N6: =M6 -> 150
A7: Transactions per Venue per Month (input) | B7: 62 | C7: 66 | D7: 70 | E7: 75 | F7: 80 | G7: 85 | H7: 90 | I7: 95 | J7: 100 | K7: 105 | L7: 110 | M7: 115 | N7: =SUM(B7:M7) -> 1053
A8: Monthly Transactions | B8: =B4*B7 -> 43400 | C8: =C4*C7 -> 50160 | D8: =D4*D7 -> 57400 | E8: =E4*E7 -> 66750 | F8: =F4*F7 -> 76800 | G8: =G4*G7 -> 88400 | H8: =H4*H7 -> 100800 | I8: =I4*I7 -> 114000 | ... M8: =M4*M7 -> 172500 | N8: =SUM(B8:M8) -> 1199410
A9: New Users Acquired (this month — input) | B9: 5000 | C9: 7000 | D9: 9000 | E9: 11000 | F9: 12000 | G9: 13000 | H9: 13000 | I9: 13000 | J9: 13000 | K9: 13000 | L9: 13000 | M9: 12053 | N9: =SUM(B9:M9) -> 134053
A10: Active Users — CUMULATIVE | B10: ='Y2 2028 Pre-Seed'!N10+B9 -> 30115 | C10: =B10+C9 -> 37115 | D10: =C10+D9 -> 46115 | E10: =D10+E9 -> 57115 | F10: =E10+F9 -> 69115 | G10: =F10+G9 -> 82115 | H10: =G10+H9 -> 95115 | I10: =H10+I9 -> 108115 | J10: =I10+J9 -> 121115 | ... M10: =L10+M9 -> 159168 | N10: =M10 -> 159168
A11: Analytics Adoption % (input) | B11: 0.48 | C11: 0.5 | D11: 0.52 | E11: 0.54 | F11: 0.56 | G11: 0.58 | H11: 0.6 | I11: 0.62 | J11: 0.64 | K11: 0.66 | L11: 0.68 | M11: 0.7 | N11: =M11 -> 0.7
A12: Premium Partner Adoption % (input) | B12: 0.27 | C12: 0.29 | D12: 0.31 | E12: 0.33 | F12: 0.35 | G12: 0.36 | H12: 0.37 | I12: 0.38 | J12: 0.39 | K12: 0.4 | L12: 0.4 | M12: 0.4 | N12: =M12 -> 0.4
A14: REVENUE
A15: Stream 1: Standard Tx Fee (×Assumptions!B15) | B15: =B8*(1-B12)*Assumptions!B15 -> 47523 | C15: =C8*(1-C12)*Assumptions!B15 -> 53420.4 | D15: =D8*(1-D12)*Assumptions!B15 -> 59409 | E15: =E8*(1-E12)*Assumptions!B15 -> 67083.75 | F15: =F8*(1-F12)*Assumptions!B15 -> 74880 | G15: =G8*(1-G12)*Assumptions!B15 -> 84864 | H15: =H8*(1-H12)*Assumptions!B15 -> 95256 | I15: =I8*(1-I12)*Assumptions!B15 -> 106020 | J15: =J8*(1-J12)*Assumptions!B15 -> 117120 | K15: =K8*(1-K12)*Assumptions!B15 -> 128520 | L15: =L8*(1-L12)*Assumptions!B15 -> 142560 | M15: =M8*(1-M12)*Assumptions!B15 -> 155250 | N15: =SUM(B15:M15) -> 1131906.1
A16: Stream 3: Premium Placement Fee (×Assumptions!B16) | B16: =B8*B12*Assumptions!B16 -> 23436 | C16: =C8*C12*Assumptions!B16 -> 29092.8 | D16: =D8*D12*Assumptions!B16 -> 35588 | E16: =E8*E12*Assumptions!B16 -> 44055 | F16: =F8*F12*Assumptions!B16 -> 53760 | G16: =G8*G12*Assumptions!B16 -> 63648 | H16: =H8*H12*Assumptions!B16 -> 74592 | I16: =I8*I12*Assumptions!B16 -> 86640 | J16: =J8*J12*Assumptions!B16 -> 99840 | K16: =K8*K12*Assumptions!B16 -> 114240 | L16: =L8*L12*Assumptions!B16 -> 126720 | M16: =M8*M12*Assumptions!B16 -> 138000 | N16: =SUM(B16:M16) -> 889611.8
A17: Stream 2: Analytics Subscription (×Assumptions!B20) | B17: =B6*B11*Assumptions!B20 -> 11760 | C17: =C6*C11*Assumptions!B20 -> 13300 | D17: =D6*D11*Assumptions!B20 -> 14924 | E17: =E6*E11*Assumptions!B20 -> 16821 | F17: =F6*F11*Assumptions!B20 -> 18816 | G17: =G6*G11*Assumptions!B20 -> 21112 | H17: =H6*H11*Assumptions!B20 -> 23520 | I17: =I6*I11*Assumptions!B20 -> 26040 | J17: =J6*J11*Assumptions!B20 -> 28672 | K17: =K6*K11*Assumptions!B20 -> 31416 | L17: =L6*L11*Assumptions!B20 -> 34272 | M17: =M6*M11*Assumptions!B20 -> 36750 | N17: =SUM(B17:M17) -> 277403
A18: Sponsored Drops (input) | B18: 0 | C18: 0 | D18: 1000 | E18: 1500 | F18: 2000 | G18: 2000 | H18: 2500 | I18: 2500 | J18: 3000 | K18: 3000 | L18: 3000 | M18: 3500 | N18: =SUM(B18:M18) -> 24000
A19: TOTAL REVENUE | B19: =B15+B16+B17+B18 -> 82719 | C19: =C15+C16+C17+C18 -> 95813.2 | D19: =D15+D16+D17+D18 -> 110921 | E19: =E15+E16+E17+E18 -> 129459.75 | F19: =F15+F16+F17+F18 -> 149456 | G19: =G15+G16+G17+G18 -> 171624 | H19: =H15+H16+H17+H18 -> 195868 | I19: =I15+I16+I17+I18 -> 221200 | ... M19: =M15+M16+M17+M18 -> 333500 | N19: =SUM(B19:M19) -> 2322921
A20: COST OF REVENUE (=Monthly Tx × Assumptions!B17)
A21: API Costs | B21: =B8*Assumptions!B17 -> 19964 | C21: =C8*Assumptions!B17 -> 23073.6 | D21: =D8*Assumptions!B17 -> 26404 | E21: =E8*Assumptions!B17 -> 30705 | F21: =F8*Assumptions!B17 -> 35328 | G21: =G8*Assumptions!B17 -> 40664 | H21: =H8*Assumptions!B17 -> 46368 | I21: =I8*Assumptions!B17 -> 52440 | J21: =J8*Assumptions!B17 -> 58880 | K21: =K8*Assumptions!B17 -> 65688 | L21: =L8*Assumptions!B17 -> 72864 | M21: =M8*Assumptions!B17 -> 79350 | N21: =SUM(B21:M21) -> 551728.6
A22: GROSS PROFIT | B22: =B19-B21 -> 62755 | C22: =C19-C21 -> 72739.6 | D22: =D19-D21 -> 84517 | E22: =E19-E21 -> 98754.75 | F22: =F19-F21 -> 114128 | G22: =G19-G21 -> 130960 | H22: =H19-H21 -> 149500 | I22: =I19-I21 -> 168760 | ... M22: =M19-M21 -> 254150 | N22: =SUM(B22:M22) -> 1771192.4
A23: Gross Margin % | B23: =IFERROR(B22/B19,0) -> 0.75865279 | C23: =IFERROR(C22/C19,0) -> 0.75918141 | D23: =IFERROR(D22/D19,0) -> 0.76195671 | E23: =IFERROR(E22/E19,0) -> 0.76282204 | F23: =IFERROR(F22/F19,0) -> 0.76362274 | G23: =IFERROR(G22/G19,0) -> 0.76306344 | H23: =IFERROR(H22/H19,0) -> 0.76326914 | I23: =IFERROR(I22/I19,0) -> 0.76292948 | ... N23: =IFERROR(N22/N19,0) -> 0.76248499
A25: OPERATING EXPENSES
A26: HEADCOUNT
A27: Full Headcount (formula-driven from Assumptions tab) | B27: 65000 | C27: 65000 | D27: 65000 | E27: 65000 | F27: 65000 | G27: 65000 | H27: 65000 | I27: 65000 | J27: 65000 | K27: 65000 | L27: 65000 | M27: 65000 | N27: =SUM(B27:M27) -> 780000
A28: TOTAL HEADCOUNT | B28: =B27 -> 65000 | C28: =C27 -> 65000 | D28: =D27 -> 65000 | E28: =E27 -> 65000 | F28: =F27 -> 65000 | G28: =G27 -> 65000 | H28: =H27 -> 65000 | I28: =I27 -> 65000 | ... M28: =M27 -> 65000 | N28: =SUM(B28:M28) -> 780000
A29: MARKETING & DINER ACQUISITION
A30: PLG Referral Bonus | B30: =B9*Assumptions!B28*Assumptions!B26 -> 15000 | C30: =C9*Assumptions!B28*Assumptions!B26 -> 21000 | D30: =D9*Assumptions!B28*Assumptions!B26 -> 27000 | E30: =E9*Assumptions!B28*Assumptions!B26 -> 33000 | F30: =F9*Assumptions!B28*Assumptions!B26 -> 36000 | G30: =G9*Assumptions!B28*Assumptions!B26 -> 39000 | H30: =H9*Assumptions!B28*Assumptions!B26 -> 39000 | I30: =I9*Assumptions!B28*Assumptions!B26 -> 39000 | J30: =J9*Assumptions!B28*Assumptions!B26 -> 39000 | K30: =K9*Assumptions!B28*Assumptions!B26 -> 39000 | L30: =L9*Assumptions!B28*Assumptions!B26 -> 39000 | M30: =M9*Assumptions!B28*Assumptions!B26 -> 36159 | N30: =SUM(B30:M30) -> 402159
A31: Performance Marketing (input) | B31: 60000 | C31: =B31*1.2 -> 72000 | D31: 86000 | E31: 100000 | F31: =E31*1.2 -> 120000 | G31: 145000 | H31: 175000 | I31: 210000 | J31: 210000 | K31: 210000 | L31: 210000 | M31: 210000 | N31: =SUM(B31:M31) -> 1808000
A32: Content Creation & Influencer (input) | B32: 8000 | C32: 8000 | D32: 8000 | E32: 8000 | F32: 8000 | G32: 8000 | H32: 8000 | I32: 8000 | J32: 8000 | K32: 8000 | L32: 8000 | M32: 8000 | N32: =SUM(B32:M32) -> 96000
A33: Events & Brand Partnerships (input) | B33: 5000 | C33: 5000 | D33: 5000 | E33: 5000 | F33: 8000 | G33: 8000 | H33: 8000 | I33: 8000 | J33: 10000 | K33: 10000 | L33: 10000 | M33: 10000 | N33: =SUM(B33:M33) -> 92000
A34: TOTAL MARKETING | B34: =SUM(B30:B33) -> 88000 | C34: =SUM(C30:C33) -> 106000 | D34: =SUM(D30:D33) -> 126000 | E34: =SUM(E30:E33) -> 146000 | F34: =SUM(F30:F33) -> 172000 | G34: =SUM(G30:G33) -> 200000 | H34: =SUM(H30:H33) -> 230000 | I34: =SUM(I30:I33) -> 265000 | ... M34: =SUM(M30:M33) -> 264159 | N34: =SUM(B34:M34) -> 2398159
A35: Restaurant Partner Acquisition (input) | B35: 5000 | C35: 5000 | D35: 5000 | E35: 5000 | F35: 5000 | G35: 5000 | H35: 5000 | I35: 5000 | J35: 5000 | K35: 5000 | L35: 5000 | M35: 5000 | N35: =SUM(B35:M35) -> 60000
A36: AI Outreach Tools (input) | B36: 500 | C36: 500 | D36: 500 | E36: 500 | F36: 500 | G36: 500 | H36: 500 | I36: 500 | J36: 500 | K36: 500 | L36: 500 | M36: 500 | N36: =SUM(B36:M36) -> 6000
A37: Tech Infrastructure (input) | B37: 3000 | C37: 3000 | D37: 3000 | E37: 3000 | F37: 3000 | G37: 3000 | H37: 3000 | I37: 3000 | J37: 3000 | K37: 3000 | L37: 3000 | M37: 3000 | N37: =SUM(B37:M37) -> 36000
A38: Office & Operations (input) | B38: 4000 | C38: 4000 | D38: 4000 | E38: 4000 | F38: 4000 | G38: 4000 | H38: 4000 | I38: 4000 | J38: 4000 | K38: 4000 | L38: 4000 | M38: 4000 | N38: =SUM(B38:M38) -> 48000
A39: Legal & Compliance (input) | B39: 2500 | C39: 2500 | D39: 2500 | E39: 2500 | F39: 2500 | G39: 2500 | H39: 2500 | I39: 2500 | J39: 2500 | K39: 2500 | L39: 2500 | M39: 2500 | N39: =SUM(B39:M39) -> 30000
A40: Miscellaneous (input) | B40: 3000 | C40: 3000 | D40: 3000 | E40: 3000 | F40: 3000 | G40: 3000 | H40: 3000 | I40: 3000 | J40: 3000 | K40: 3000 | L40: 3000 | M40: 3000 | N40: =SUM(B40:M40) -> 36000
A41: TOTAL OPEX | B41: =B28+B34+B35+B36+B37+B38+B39+B40 -> 171000 | C41: =C28+C34+C35+C36+C37+C38+C39+C40 -> 189000 | D41: =D28+D34+D35+D36+D37+D38+D39+D40 -> 209000 | E41: =E28+E34+E35+E36+E37+E38+E39+E40 -> 229000 | F41: =F28+F34+F35+F36+F37+F38+F39+F40 -> 255000 | G41: =G28+G34+G35+G36+G37+G38+G39+G40 -> 283000 | H41: =H28+H34+H35+H36+H37+H38+H39+H40 -> 313000 | I41: =I28+I34+I35+I36+I37+I38+I39+I40 -> 348000 | ... M41: =M28+M34+M35+M36+M37+M38+M39+M40 -> 347159 | N41: =SUM(B41:M41) -> 3394159
A44: EBITDA (=Gross Profit - Total OPEX) | B44: =B22-B41 -> -108245 | C44: =C22-C41 -> -116260.4 | D44: =D22-D41 -> -124483 | E44: =E22-E41 -> -130245.25 | F44: =F22-F41 -> -140872 | G44: =G22-G41 -> -152040 | H44: =H22-H41 -> -163500 | I44: =I22-I41 -> -179240 | ... M44: =M22-M41 -> -93009 | N44: =SUM(B44:M44) -> -1622966.6
...

Sheet Y4 2030 Series A
A1: KLAIM UK — Y4 SERIES A (Jan–Dec 2030) | £8M Raise | Maximum Deployment | Target £1.5M Closing Cash
A2: LINE ITEM | B2: Jan 30 | C2: Feb 30 | D2: Mar 30 | E2: Apr 30 | F2: May 30 | G2: Jun 30 | H2: Jul 30 | I2: Aug 30 | J2: Sep 30 | K2: Oct 30 | L2: Nov 30 | M2: Dec 30 | N2: FULL YEAR
A3: OPERATING ASSUMPTIONS (yellow = input)
A4: Restaurant Venues (end of month) | B4: 1600 | C4: 1750 | D4: 1900 | E4: 2100 | F4: 2300 | G4: 2500 | H4: 2700 | I4: 2900 | J4: 3100 | K4: 3300 | L4: 3500 | M4: 3700 | N4: =M4 -> 3700
A5: New Restaurant Venues Acquired per Month | B5: =B4-'Y3 2029 Seed'!M4 -> 100 | C5: =C4-B4 -> 150 | D5: =D4-C4 -> 150 | E5: =E4-D4 -> 200 | F5: =F4-E4 -> 200 | G5: =G4-F4 -> 200 | H5: =H4-G4 -> 200 | I5: =I4-H4 -> 200 | J5: =J4-I4 -> 200 | ... M5: =M4-L4 -> 200 | N5: =SUM(B5:M5) -> 2200
A6: Restaurant Brands (÷ Assumptions!B21) | B6: =B4/Assumptions!B21 -> 160 | C6: =C4/Assumptions!B21 -> 175 | D6: =D4/Assumptions!B21 -> 190 | E6: =E4/Assumptions!B21 -> 210 | F6: =F4/Assumptions!B21 -> 230 | G6: =G4/Assumptions!B21 -> 250 | H6: =H4/Assumptions!B21 -> 270 | I6: =I4/Assumptions!B21 -> 290 | J6: =J4/Assumptions!B21 -> 310 | K6: =K4/Assumptions!B21 -> 330 | L6: =L4/Assumptions!B21 -> 350 | M6: =M4/Assumptions!B21 -> 370 | N6: =M6 -> 370
A7: Transactions per Venue per Month (input) | B7: 120 | C7: 125 | D7: 130 | E7: 135 | F7: 140 | G7: 145 | H7: 150 | I7: 155 | J7: 160 | K7: 165 | L7: 170 | M7: 175 | N7: =SUM(B7:M7) -> 1770
A8: Monthly Transactions | B8: =B4*B7 -> 192000 | C8: =C4*C7 -> 218750 | D8: =D4*D7 -> 247000 | E8: =E4*E7 -> 283500 | F8: =F4*F7 -> 322000 | G8: =G4*G7 -> 362500 | H8: =H4*H7 -> 405000 | I8: =I4*I7 -> 449500 | ... M8: =M4*M7 -> 647500 | N8: =SUM(B8:M8) -> 4763250
A9: New Users Acquired (this month — input) | B9: 20000 | C9: 25000 | D9: 30000 | E9: 35000 | F9: 40000 | G9: 45000 | H9: 45000 | I9: 45000 | J9: 45000 | K9: 50000 | L9: 50000 | M9: 47990 | N9: =SUM(B9:M9) -> 477990
A10: Active Users — CUMULATIVE | B10: ='Y3 2029 Seed'!N10+B9 -> 179168 | C10: =B10+C9 -> 204168 | D10: =C10+D9 -> 234168 | E10: =D10+E9 -> 269168 | F10: =E10+F9 -> 309168 | G10: =F10+G9 -> 354168 | H10: =G10+H9 -> 399168 | I10: =H10+I9 -> 444168 | J10: =I10+J9 -> 489168 | ... M10: =L10+M9 -> 637158 | N10: =M10 -> 637158
A11: Analytics Adoption % (input) | B11: 0.72 | C11: 0.73 | D11: 0.74 | E11: 0.75 | F11: 0.76 | G11: 0.77 | H11: 0.78 | I11: 0.79 | J11: 0.8 | K11: 0.81 | L11: 0.82 | M11: 0.83 | N11: =M11 -> 0.83
A12: Premium Partner Adoption % (input) | B12: 0.42 | C12: 0.44 | D12: 0.46 | E12: 0.48 | F12: 0.5 | G12: 0.51 | H12: 0.52 | I12: 0.53 | J12: 0.54 | K12: 0.55 | L12: 0.55 | M12: 0.55 | N12: =M12 -> 0.55
A14: REVENUE
A15: Stream 1: Standard Tx Fee (×Assumptions!B15) | B15: =B8*(1-B12)*Assumptions!B15 -> 167040 | C15: =C8*(1-C12)*Assumptions!B15 -> 183750 | D15: =D8*(1-D12)*Assumptions!B15 -> 200070 | E15: =E8*(1-E12)*Assumptions!B15 -> 221130 | F15: =F8*(1-F12)*Assumptions!B15 -> 241500 | G15: =G8*(1-G12)*Assumptions!B15 -> 266437.5 | H15: =H8*(1-H12)*Assumptions!B15 -> 291600 | I15: =I8*(1-I12)*Assumptions!B15 -> 316897.5 | J15: =J8*(1-J12)*Assumptions!B15 -> 342240 | K15: =K8*(1-K12)*Assumptions!B15 -> 367537.5 | L15: =L8*(1-L12)*Assumptions!B15 -> 401625 | M15: =M8*(1-M12)*Assumptions!B15 -> 437062.5 | N15: =SUM(B15:M15) -> 3436890
A16: Stream 3: Premium Placement Fee (×Assumptions!B16) | B16: =B8*B12*Assumptions!B16 -> 161280 | C16: =C8*C12*Assumptions!B16 -> 192500 | D16: =D8*D12*Assumptions!B16 -> 227240 | E16: =E8*E12*Assumptions!B16 -> 272160 | F16: =F8*F12*Assumptions!B16 -> 322000 | G16: =G8*G12*Assumptions!B16 -> 369750 | H16: =H8*H12*Assumptions!B16 -> 421200 | I16: =I8*I12*Assumptions!B16 -> 476470 | J16: =J8*J12*Assumptions!B16 -> 535680 | K16: =K8*K12*Assumptions!B16 -> 598950 | L16: =L8*L12*Assumptions!B16 -> 654500 | M16: =M8*M12*Assumptions!B16 -> 712250 | N16: =SUM(B16:M16) -> 4943980
A17: Stream 2: Analytics Subscription (×Assumptions!B20) | B17: =B6*B11*Assumptions!B20 -> 40320 | C17: =C6*C11*Assumptions!B20 -> 44712.5 | D17: =D6*D11*Assumptions!B20 -> 49210 | E17: =E6*E11*Assumptions!B20 -> 55125 | F17: =F6*F11*Assumptions!B20 -> 61180 | G17: =G6*G11*Assumptions!B20 -> 67375 | H17: =H6*H11*Assumptions!B20 -> 73710 | I17: =I6*I11*Assumptions!B20 -> 80185 | J17: =J6*J11*Assumptions!B20 -> 86800 | K17: =K6*K11*Assumptions!B20 -> 93555 | L17: =L6*L11*Assumptions!B20 -> 100450 | M17: =M6*M11*Assumptions!B20 -> 107485 | N17: =SUM(B17:M17) -> 860107.5
A18: Sponsored Drops (input) | B18: 4000 | C18: 5000 | D18: 6000 | E18: 8000 | F18: 10000 | G18: 12000 | H18: 13000 | I18: 14000 | J18: 15000 | K18: 15000 | L18: 16000 | M18: 17000 | N18: =SUM(B18:M18) -> 135000
A19: Data Platform & Consultancy (input) | B19: 0 | C19: 0 | D19: 0 | E19: 0 | F19: 0 | G19: 8000 | H19: 8000 | I19: 10000 | J19: 10000 | K19: 12000 | L19: 12000 | M19: 15000 | N19: =SUM(B19:M19) -> 75000
A20: TOTAL REVENUE | B20: =B15+B16+B17+B18+B19 -> 372640 | C20: =C15+C16+C17+C18+C19 -> 425962.5 | D20: =D15+D16+D17+D18+D19 -> 482520 | E20: =E15+E16+E17+E18+E19 -> 556415 | F20: =F15+F16+F17+F18+F19 -> 634680 | G20: =G15+G16+G17+G18+G19 -> 723562.5 | H20: =H15+H16+H17+H18+H19 -> 807510 | I20: =I15+I16+I17+I18+I19 -> 897552.5 | ... M20: =M15+M16+M17+M18+M19 -> 1288797.5 | N20: =SUM(B20:M20) -> 9450977.5
A21: COST OF REVENUE (=Monthly Tx × Assumptions!B17)
A22: API Costs | B22: =B8*Assumptions!B17 -> 88320 | C22: =C8*Assumptions!B17 -> 100625 | D22: =D8*Assumptions!B17 -> 113620 | E22: =E8*Assumptions!B17 -> 130410 | F22: =F8*Assumptions!B17 -> 148120 | G22: =G8*Assumptions!B17 -> 166750 | H22: =H8*Assumptions!B17 -> 186300 | I22: =I8*Assumptions!B17 -> 206770 | J22: =J8*Assumptions!B17 -> 228160 | K22: =K8*Assumptions!B17 -> 250470 | L22: =L8*Assumptions!B17 -> 273700 | M22: =M8*Assumptions!B17 -> 297850 | N22: =SUM(B22:M22) -> 2191095
A23: GROSS PROFIT | B23: =B20-B22 -> 284320 | C23: =C20-C22 -> 325337.5 | D23: =D20-D22 -> 368900 | E23: =E20-E22 -> 426005 | F23: =F20-F22 -> 486560 | G23: =G20-G22 -> 556812.5 | H23: =H20-H22 -> 621210 | I23: =I20-I22 -> 690782.5 | ... M23: =M20-M22 -> 990947.5 | N23: =SUM(B23:M23) -> 7259882.5
A24: Gross Margin % | B24: =IFERROR(B23/B20,0) -> 0.76298841 | C24: =IFERROR(C23/C20,0) -> 0.76377028 | D24: =IFERROR(D23/D20,0) -> 0.7645279 | E24: =IFERROR(E23/E20,0) -> 0.76562458 | F24: =IFERROR(F23/F20,0) -> 0.76662255 | G24: =IFERROR(G23/G20,0) -> 0.76954306 | H24: =IFERROR(H23/H20,0) -> 0.76929078 | I24: =IFERROR(I23/I20,0) -> 0.76962907 | ... N24: =IFERROR(N23/N20,0) -> 0.76816208
A26: OPERATING EXPENSES
A27: HEADCOUNT
A28: Full Headcount (formula-driven from Assumptions tab) | B28: 150000 | C28: 150000 | D28: 150000 | E28: 150000 | F28: 150000 | G28: 150000 | H28: 150000 | I28: 150000 | J28: 150000 | K28: 150000 | L28: 150000 | M28: 150000 | N28: =SUM(B28:M28) -> 1800000
A29: TOTAL HEADCOUNT | B29: =B28 -> 150000 | C29: =C28 -> 150000 | D29: =D28 -> 150000 | E29: =E28 -> 150000 | F29: =F28 -> 150000 | G29: =G28 -> 150000 | H29: =H28 -> 150000 | I29: =I28 -> 150000 | ... M29: =M28 -> 150000 | N29: =SUM(B29:M29) -> 1800000
A30: MARKETING & DINER ACQUISITION
A31: PLG Referral Bonus | B31: =B9*Assumptions!B28*Assumptions!B26 -> 60000 | C31: =C9*Assumptions!B28*Assumptions!B26 -> 75000 | D31: =D9*Assumptions!B28*Assumptions!B26 -> 90000 | E31: =E9*Assumptions!B28*Assumptions!B26 -> 105000 | F31: =F9*Assumptions!B28*Assumptions!B26 -> 120000 | G31: =G9*Assumptions!B28*Assumptions!B26 -> 135000 | H31: =H9*Assumptions!B28*Assumptions!B26 -> 135000 | I31: =I9*Assumptions!B28*Assumptions!B26 -> 135000 | J31: =J9*Assumptions!B28*Assumptions!B26 -> 135000 | K31: =K9*Assumptions!B28*Assumptions!B26 -> 150000 | L31: =L9*Assumptions!B28*Assumptions!B26 -> 150000 | M31: 150000 | N31: =SUM(B31:M31) -> 1440000
A32: Performance Marketing (input) | B32: 300000 | C32: =B32*1.2 -> 360000 | D32: =C32*1.2 -> 432000 | E32: 520000 | F32: 622000 | G32: 750000 | H32: 750000 | I32: 750000 | J32: 750000 | K32: 750000 | L32: 750000 | M32: 750000 | N32: =SUM(B32:M32) -> 7484000
A33: Content Creation & Influencer (input) | B33: 12000 | C33: 12000 | D33: 12000 | E33: 12000 | F33: 12000 | G33: 12000 | H33: 12000 | I33: 12000 | J33: 12000 | K33: 12000 | L33: 12000 | M33: 12000 | N33: =SUM(B33:M33) -> 144000
A34: Events & Brand Partnerships (input) | B34: 10000 | C34: 10000 | D34: 12000 | E34: 12000 | F34: 15000 | G34: 15000 | H34: 15000 | I34: 15000 | J34: 18000 | K34: 18000 | L34: 18000 | M34: 18000 | N34: =SUM(B34:M34) -> 176000
A35: TOTAL MARKETING | B35: =SUM(B31:B34) -> 382000 | C35: =SUM(C31:C34) -> 457000 | D35: =SUM(D31:D34) -> 546000 | E35: =SUM(E31:E34) -> 649000 | F35: =SUM(F31:F34) -> 769000 | G35: =SUM(G31:G34) -> 912000 | H35: =SUM(H31:H34) -> 912000 | I35: =SUM(I31:I34) -> 912000 | ... M35: =SUM(M31:M34) -> 930000 | N35: =SUM(B35:M35) -> 9244000
A36: Restaurant Partner Acquisition (input) | B36: 8000 | C36: 8000 | D36: 8000 | E36: 8000 | F36: 8000 | G36: 8000 | H36: 8000 | I36: 8000 | J36: 8000 | K36: 8000 | L36: 8000 | M36: 8000 | N36: =SUM(B36:M36) -> 96000
A37: AI Outreach Tools (input) | B37: 500 | C37: 500 | D37: 500 | E37: 500 | F37: 500 | G37: 500 | H37: 500 | I37: 500 | J37: 500 | K37: 500 | L37: 500 | M37: 500 | N37: =SUM(B37:M37) -> 6000
A38: Tech Infrastructure (input) | B38: 8000 | C38: 8000 | D38: 8000 | E38: 8000 | F38: 8000 | G38: 8000 | H38: 8000 | I38: 8000 | J38: 8000 | K38: 8000 | L38: 8000 | M38: 8000 | N38: =SUM(B38:M38) -> 96000
A39: Office & Operations (input) | B39: 8000 | C39: 8000 | D39: 8000 | E39: 8000 | F39: 8000 | G39: 8000 | H39: 8000 | I39: 8000 | J39: 8000 | K39: 8000 | L39: 8000 | M39: 8000 | N39: =SUM(B39:M39) -> 96000
A40: Legal & Compliance (input) | B40: 3500 | C40: 3500 | D40: 3500 | E40: 3500 | F40: 3500 | G40: 3500 | H40: 3500 | I40: 3500 | J40: 3500 | K40: 3500 | L40: 3500 | M40: 3500 | N40: =SUM(B40:M40) -> 42000
A41: Miscellaneous (input) | B41: 5000 | C41: 5000 | D41: 5000 | E41: 5000 | F41: 5000 | G41: 5000 | H41: 5000 | I41: 5000 | J41: 5000 | K41: 5000 | L41: 5000 | M41: 5000 | N41: =SUM(B41:M41) -> 60000
A42: TOTAL OPEX | B42: =B29+B35+B36+B37+B38+B39+B40+B41 -> 565000 | C42: =C29+C35+C36+C37+C38+C39+C40+C41 -> 640000 | D42: =D29+D35+D36+D37+D38+D39+D40+D41 -> 729000 | E42: =E29+E35+E36+E37+E38+E39+E40+E41 -> 832000 | F42: =F29+F35+F36+F37+F38+F39+F40+F41 -> 952000 | G42: =G29+G35+G36+G37+G38+G39+G40+G41 -> 1095000 | H42: =H29+H35+H36+H37+H38+H39+H40+H41 -> 1095000 | I42: =I29+I35+I36+I37+I38+I39+I40+I41 -> 1095000 | ... M42: =M29+M35+M36+M37+M38+M39+M40+M41 -> 1113000 | N42: =SUM(B42:M42) -> 11440000
...

Sheet 4-Year Annual Summary
A1: KLAIM UK — 4-YEAR ANNUAL P&L SUMMARY | All figures pull from individual year tabs
A3: METRIC | B3: 2027 Bootstrap | C3: 2028 Pre-Seed | D3: 2029 Seed | E3: 2030 Series A | F3: 4-YEAR TOTAL
A4: REVENUE
A5: Total Revenue | B5: ='Y1 2027 Bootstrap'!O17 -> 95905 | C5: ='Y2 2028 Pre-Seed'!N18 -> 525483.9 | D5: ='Y3 2029 Seed'!N19 -> 2322921 | E5: ='Y4 2030 Series A'!N20 -> 9450977.5 | F5: =SUM(B5:E5) -> 12395287
A6: Gross Profit | B6: ='Y1 2027 Bootstrap'!O20 -> 68898.4 | C6: ='Y2 2028 Pre-Seed'!N21 -> 396481.5 | D6: ='Y3 2029 Seed'!N22 -> 1771192.4 | E6: ='Y4 2030 Series A'!N23 -> 7259882.5 | F6: =SUM(B6:E6) -> 9496454.8
A7: Gross Margin % | B7: =IFERROR('Y1 2027 Bootstrap'!O20/'Y1 2027 Bootstrap'!O17,0) -> 0.71840259 | C7: =IFERROR('Y2 2028 Pre-Seed'!N21/'Y2 2028 Pre-Seed'!N18,0) -> 0.75450742 | D7: =IFERROR('Y3 2029 Seed'!N22/'Y3 2029 Seed'!N19,0) -> 0.76248499 | E7: =IFERROR('Y4 2030 Series A'!N23/'Y4 2030 Series A'!N20,0) -> 0.76816208
A8: OPERATING EXPENSES
A9: Total OPEX | B9: ='Y1 2027 Bootstrap'!O43 -> 59425 | C9: ='Y2 2028 Pre-Seed'!N46 -> 876325 | D9: ='Y3 2029 Seed'!N41 -> 3394159 | E9: ='Y4 2030 Series A'!N42 -> 11440000 | F9: =SUM(B9:E9) -> 15769909
A10: Marketing Spend | B10: ='Y1 2027 Bootstrap'!O38 -> 41925 | C10: ='Y2 2028 Pre-Seed'!N39 -> 318895 | D10: ='Y3 2029 Seed'!N34 -> 2398159 | E10: ='Y4 2030 Series A'!N35 -> 9244000 | F10: =SUM(B10:E10) -> 12002979
A11: EBITDA (=Gross Profit - Total OPEX) | B11: ='Y1 2027 Bootstrap'!O46 -> 9473.4 | C11: ='Y2 2028 Pre-Seed'!N49 -> -479843.5 | D11: ='Y3 2029 Seed'!N44 -> -1622966.6 | E11: ='Y4 2030 Series A'!N45 -> -4180117.5 | F11: =SUM(B11:E11) -> -6273454.2
A13: KEY METRICS
A14: Active Users (end of year) | B14: ='Y1 2027 Bootstrap'!O10 -> 4650 | C14: ='Y2 2028 Pre-Seed'!N10 -> 25115 | D14: ='Y3 2029 Seed'!N10 -> 159168 | E14: ='Y4 2030 Series A'!N10 -> 637158 | F14: =SUM(B14:E14) -> 826091
A15: Restaurant Venues (end of year) | B15: ='Y1 2027 Bootstrap'!O4 -> 420 | C15: ='Y2 2028 Pre-Seed'!N4 -> 650 | D15: ='Y3 2029 Seed'!N4 -> 1500 | E15: ='Y4 2030 Series A'!N4 -> 3700 | F15: =SUM(B15:E15) -> 6270
A16: Closing Cash | B16: ='Y1 2027 Bootstrap'!O50 -> 39473.4 | C16: ='Y2 2028 Pre-Seed'!N53 -> 309629.9 | D16: ='Y3 2029 Seed'!N48 -> 1186663.2 | E16: ='Y4 2030 Series A'!N49 -> 5006545.8
A18: FUNDING ROADMAP
A19: Round | B19: Bootstrap | C19: Pre-Seed | D19: Seed | E19: Series A
A20: Capital | B20: 30000 | C20: 750000 | D20: 2500000 | E20: 8000000
A21: Pre-Money Valuation | B21: 1000000 | C21: 3750000 | D21: 10000000 | E21: 37000000
A22: Timing | B22: Jan 2027 | C22: Jan 2028 | D22: Jan 2029 | E22: Jan 2030
